2023-09-15 16:45:09,138 ERROR scheduler Exception in Enqueue Events for Site taskerpage.com
Traceback (most recent call last):
  File "env/lib/python3.10/site-packages/pymysql/connections.py", line 616, in connect
    sock = socket.create_connection(
  File "/usr/lib/python3.10/socket.py", line 845, in create_connection
    raise err
  File "/usr/lib/python3.10/socket.py", line 833, in create_connection
    sock.connect(sa)
ConnectionRefusedError: [Errno 111] Connection refused

During handling of the above exception, another exception occurred:

Traceback (most recent call last):
  File "apps/frappe/frappe/utils/scheduler.py", line 75, in enqueue_events_for_site
    if is_scheduler_inactive():
  File "apps/frappe/frappe/utils/scheduler.py", line 114, in is_scheduler_inactive
    if is_scheduler_disabled(verbose=verbose):
  File "apps/frappe/frappe/utils/scheduler.py", line 127, in is_scheduler_disabled
    frappe.db.get_single_value("System Settings", "enable_scheduler")
  File "apps/frappe/frappe/database/database.py", line 786, in get_single_value
    ).run()
  File "apps/frappe/frappe/query_builder/utils.py", line 87, in execute_query
    result = frappe.db.sql(query, params, *args, **kwargs)  # nosemgrep
  File "apps/frappe/frappe/database/database.py", line 201, in sql
    self.connect()
  File "apps/frappe/frappe/database/database.py", line 115, in connect
    self._conn = self.get_connection()
  File "apps/frappe/frappe/database/mariadb/database.py", line 98, in get_connection
    conn = self._get_connection()
  File "apps/frappe/frappe/database/mariadb/database.py", line 104, in _get_connection
    return self.create_connection()
  File "apps/frappe/frappe/database/mariadb/database.py", line 107, in create_connection
    return pymysql.connect(**self.get_connection_settings())
  File "env/lib/python3.10/site-packages/pymysql/connections.py", line 352, in __init__
    self.connect()
  File "env/lib/python3.10/site-packages/pymysql/connections.py", line 668, in connect
    raise exc
pymysql.err.OperationalError: (2003, "Can't connect to MySQL server on '127.0.0.1' ([Errno 111] Connection refused)")

2023-09-15 16:46:09,234 ERROR scheduler Exception in Enqueue Events for Site taskerpage.com
Traceback (most recent call last):
  File "env/lib/python3.10/site-packages/pymysql/connections.py", line 616, in connect
    sock = socket.create_connection(
  File "/usr/lib/python3.10/socket.py", line 845, in create_connection
    raise err
  File "/usr/lib/python3.10/socket.py", line 833, in create_connection
    sock.connect(sa)
ConnectionRefusedError: [Errno 111] Connection refused

During handling of the above exception, another exception occurred:

Traceback (most recent call last):
  File "apps/frappe/frappe/utils/scheduler.py", line 75, in enqueue_events_for_site
    if is_scheduler_inactive():
  File "apps/frappe/frappe/utils/scheduler.py", line 114, in is_scheduler_inactive
    if is_scheduler_disabled(verbose=verbose):
  File "apps/frappe/frappe/utils/scheduler.py", line 127, in is_scheduler_disabled
    frappe.db.get_single_value("System Settings", "enable_scheduler")
  File "apps/frappe/frappe/database/database.py", line 786, in get_single_value
    ).run()
  File "apps/frappe/frappe/query_builder/utils.py", line 87, in execute_query
    result = frappe.db.sql(query, params, *args, **kwargs)  # nosemgrep
  File "apps/frappe/frappe/database/database.py", line 201, in sql
    self.connect()
  File "apps/frappe/frappe/database/database.py", line 115, in connect
    self._conn = self.get_connection()
  File "apps/frappe/frappe/database/mariadb/database.py", line 98, in get_connection
    conn = self._get_connection()
  File "apps/frappe/frappe/database/mariadb/database.py", line 104, in _get_connection
    return self.create_connection()
  File "apps/frappe/frappe/database/mariadb/database.py", line 107, in create_connection
    return pymysql.connect(**self.get_connection_settings())
  File "env/lib/python3.10/site-packages/pymysql/connections.py", line 352, in __init__
    self.connect()
  File "env/lib/python3.10/site-packages/pymysql/connections.py", line 668, in connect
    raise exc
pymysql.err.OperationalError: (2003, "Can't connect to MySQL server on '127.0.0.1' ([Errno 111] Connection refused)")

2023-09-15 16:47:09,340 ERROR scheduler Exception in Enqueue Events for Site taskerpage.com
Traceback (most recent call last):
  File "env/lib/python3.10/site-packages/pymysql/connections.py", line 616, in connect
    sock = socket.create_connection(
  File "/usr/lib/python3.10/socket.py", line 845, in create_connection
    raise err
  File "/usr/lib/python3.10/socket.py", line 833, in create_connection
    sock.connect(sa)
ConnectionRefusedError: [Errno 111] Connection refused

During handling of the above exception, another exception occurred:

Traceback (most recent call last):
  File "apps/frappe/frappe/utils/scheduler.py", line 75, in enqueue_events_for_site
    if is_scheduler_inactive():
  File "apps/frappe/frappe/utils/scheduler.py", line 114, in is_scheduler_inactive
    if is_scheduler_disabled(verbose=verbose):
  File "apps/frappe/frappe/utils/scheduler.py", line 127, in is_scheduler_disabled
    frappe.db.get_single_value("System Settings", "enable_scheduler")
  File "apps/frappe/frappe/database/database.py", line 786, in get_single_value
    ).run()
  File "apps/frappe/frappe/query_builder/utils.py", line 87, in execute_query
    result = frappe.db.sql(query, params, *args, **kwargs)  # nosemgrep
  File "apps/frappe/frappe/database/database.py", line 201, in sql
    self.connect()
  File "apps/frappe/frappe/database/database.py", line 115, in connect
    self._conn = self.get_connection()
  File "apps/frappe/frappe/database/mariadb/database.py", line 98, in get_connection
    conn = self._get_connection()
  File "apps/frappe/frappe/database/mariadb/database.py", line 104, in _get_connection
    return self.create_connection()
  File "apps/frappe/frappe/database/mariadb/database.py", line 107, in create_connection
    return pymysql.connect(**self.get_connection_settings())
  File "env/lib/python3.10/site-packages/pymysql/connections.py", line 352, in __init__
    self.connect()
  File "env/lib/python3.10/site-packages/pymysql/connections.py", line 668, in connect
    raise exc
pymysql.err.OperationalError: (2003, "Can't connect to MySQL server on '127.0.0.1' ([Errno 111] Connection refused)")

2023-09-15 16:48:09,436 ERROR scheduler Exception in Enqueue Events for Site taskerpage.com
Traceback (most recent call last):
  File "env/lib/python3.10/site-packages/pymysql/connections.py", line 616, in connect
    sock = socket.create_connection(
  File "/usr/lib/python3.10/socket.py", line 845, in create_connection
    raise err
  File "/usr/lib/python3.10/socket.py", line 833, in create_connection
    sock.connect(sa)
ConnectionRefusedError: [Errno 111] Connection refused

During handling of the above exception, another exception occurred:

Traceback (most recent call last):
  File "apps/frappe/frappe/utils/scheduler.py", line 75, in enqueue_events_for_site
    if is_scheduler_inactive():
  File "apps/frappe/frappe/utils/scheduler.py", line 114, in is_scheduler_inactive
    if is_scheduler_disabled(verbose=verbose):
  File "apps/frappe/frappe/utils/scheduler.py", line 127, in is_scheduler_disabled
    frappe.db.get_single_value("System Settings", "enable_scheduler")
  File "apps/frappe/frappe/database/database.py", line 786, in get_single_value
    ).run()
  File "apps/frappe/frappe/query_builder/utils.py", line 87, in execute_query
    result = frappe.db.sql(query, params, *args, **kwargs)  # nosemgrep
  File "apps/frappe/frappe/database/database.py", line 201, in sql
    self.connect()
  File "apps/frappe/frappe/database/database.py", line 115, in connect
    self._conn = self.get_connection()
  File "apps/frappe/frappe/database/mariadb/database.py", line 98, in get_connection
    conn = self._get_connection()
  File "apps/frappe/frappe/database/mariadb/database.py", line 104, in _get_connection
    return self.create_connection()
  File "apps/frappe/frappe/database/mariadb/database.py", line 107, in create_connection
    return pymysql.connect(**self.get_connection_settings())
  File "env/lib/python3.10/site-packages/pymysql/connections.py", line 352, in __init__
    self.connect()
  File "env/lib/python3.10/site-packages/pymysql/connections.py", line 668, in connect
    raise exc
pymysql.err.OperationalError: (2003, "Can't connect to MySQL server on '127.0.0.1' ([Errno 111] Connection refused)")

2023-09-15 16:49:09,517 ERROR scheduler Exception in Enqueue Events for Site taskerpage.com
Traceback (most recent call last):
  File "env/lib/python3.10/site-packages/pymysql/connections.py", line 616, in connect
    sock = socket.create_connection(
  File "/usr/lib/python3.10/socket.py", line 845, in create_connection
    raise err
  File "/usr/lib/python3.10/socket.py", line 833, in create_connection
    sock.connect(sa)
ConnectionRefusedError: [Errno 111] Connection refused

During handling of the above exception, another exception occurred:

Traceback (most recent call last):
  File "apps/frappe/frappe/utils/scheduler.py", line 75, in enqueue_events_for_site
    if is_scheduler_inactive():
  File "apps/frappe/frappe/utils/scheduler.py", line 114, in is_scheduler_inactive
    if is_scheduler_disabled(verbose=verbose):
  File "apps/frappe/frappe/utils/scheduler.py", line 127, in is_scheduler_disabled
    frappe.db.get_single_value("System Settings", "enable_scheduler")
  File "apps/frappe/frappe/database/database.py", line 786, in get_single_value
    ).run()
  File "apps/frappe/frappe/query_builder/utils.py", line 87, in execute_query
    result = frappe.db.sql(query, params, *args, **kwargs)  # nosemgrep
  File "apps/frappe/frappe/database/database.py", line 201, in sql
    self.connect()
  File "apps/frappe/frappe/database/database.py", line 115, in connect
    self._conn = self.get_connection()
  File "apps/frappe/frappe/database/mariadb/database.py", line 98, in get_connection
    conn = self._get_connection()
  File "apps/frappe/frappe/database/mariadb/database.py", line 104, in _get_connection
    return self.create_connection()
  File "apps/frappe/frappe/database/mariadb/database.py", line 107, in create_connection
    return pymysql.connect(**self.get_connection_settings())
  File "env/lib/python3.10/site-packages/pymysql/connections.py", line 352, in __init__
    self.connect()
  File "env/lib/python3.10/site-packages/pymysql/connections.py", line 668, in connect
    raise exc
pymysql.err.OperationalError: (2003, "Can't connect to MySQL server on '127.0.0.1' ([Errno 111] Connection refused)")

2023-09-15 16:50:09,612 ERROR scheduler Exception in Enqueue Events for Site taskerpage.com
Traceback (most recent call last):
  File "env/lib/python3.10/site-packages/pymysql/connections.py", line 616, in connect
    sock = socket.create_connection(
  File "/usr/lib/python3.10/socket.py", line 845, in create_connection
    raise err
  File "/usr/lib/python3.10/socket.py", line 833, in create_connection
    sock.connect(sa)
ConnectionRefusedError: [Errno 111] Connection refused

During handling of the above exception, another exception occurred:

Traceback (most recent call last):
  File "apps/frappe/frappe/utils/scheduler.py", line 75, in enqueue_events_for_site
    if is_scheduler_inactive():
  File "apps/frappe/frappe/utils/scheduler.py", line 114, in is_scheduler_inactive
    if is_scheduler_disabled(verbose=verbose):
  File "apps/frappe/frappe/utils/scheduler.py", line 127, in is_scheduler_disabled
    frappe.db.get_single_value("System Settings", "enable_scheduler")
  File "apps/frappe/frappe/database/database.py", line 786, in get_single_value
    ).run()
  File "apps/frappe/frappe/query_builder/utils.py", line 87, in execute_query
    result = frappe.db.sql(query, params, *args, **kwargs)  # nosemgrep
  File "apps/frappe/frappe/database/database.py", line 201, in sql
    self.connect()
  File "apps/frappe/frappe/database/database.py", line 115, in connect
    self._conn = self.get_connection()
  File "apps/frappe/frappe/database/mariadb/database.py", line 98, in get_connection
    conn = self._get_connection()
  File "apps/frappe/frappe/database/mariadb/database.py", line 104, in _get_connection
    return self.create_connection()
  File "apps/frappe/frappe/database/mariadb/database.py", line 107, in create_connection
    return pymysql.connect(**self.get_connection_settings())
  File "env/lib/python3.10/site-packages/pymysql/connections.py", line 352, in __init__
    self.connect()
  File "env/lib/python3.10/site-packages/pymysql/connections.py", line 668, in connect
    raise exc
pymysql.err.OperationalError: (2003, "Can't connect to MySQL server on '127.0.0.1' ([Errno 111] Connection refused)")

2023-09-15 16:51:09,705 ERROR scheduler Exception in Enqueue Events for Site taskerpage.com
Traceback (most recent call last):
  File "env/lib/python3.10/site-packages/pymysql/connections.py", line 616, in connect
    sock = socket.create_connection(
  File "/usr/lib/python3.10/socket.py", line 845, in create_connection
    raise err
  File "/usr/lib/python3.10/socket.py", line 833, in create_connection
    sock.connect(sa)
ConnectionRefusedError: [Errno 111] Connection refused

During handling of the above exception, another exception occurred:

Traceback (most recent call last):
  File "apps/frappe/frappe/utils/scheduler.py", line 75, in enqueue_events_for_site
    if is_scheduler_inactive():
  File "apps/frappe/frappe/utils/scheduler.py", line 114, in is_scheduler_inactive
    if is_scheduler_disabled(verbose=verbose):
  File "apps/frappe/frappe/utils/scheduler.py", line 127, in is_scheduler_disabled
    frappe.db.get_single_value("System Settings", "enable_scheduler")
  File "apps/frappe/frappe/database/database.py", line 786, in get_single_value
    ).run()
  File "apps/frappe/frappe/query_builder/utils.py", line 87, in execute_query
    result = frappe.db.sql(query, params, *args, **kwargs)  # nosemgrep
  File "apps/frappe/frappe/database/database.py", line 201, in sql
    self.connect()
  File "apps/frappe/frappe/database/database.py", line 115, in connect
    self._conn = self.get_connection()
  File "apps/frappe/frappe/database/mariadb/database.py", line 98, in get_connection
    conn = self._get_connection()
  File "apps/frappe/frappe/database/mariadb/database.py", line 104, in _get_connection
    return self.create_connection()
  File "apps/frappe/frappe/database/mariadb/database.py", line 107, in create_connection
    return pymysql.connect(**self.get_connection_settings())
  File "env/lib/python3.10/site-packages/pymysql/connections.py", line 352, in __init__
    self.connect()
  File "env/lib/python3.10/site-packages/pymysql/connections.py", line 668, in connect
    raise exc
pymysql.err.OperationalError: (2003, "Can't connect to MySQL server on '127.0.0.1' ([Errno 111] Connection refused)")

2023-09-15 16:52:09,801 ERROR scheduler Exception in Enqueue Events for Site taskerpage.com
Traceback (most recent call last):
  File "env/lib/python3.10/site-packages/pymysql/connections.py", line 616, in connect
    sock = socket.create_connection(
  File "/usr/lib/python3.10/socket.py", line 845, in create_connection
    raise err
  File "/usr/lib/python3.10/socket.py", line 833, in create_connection
    sock.connect(sa)
ConnectionRefusedError: [Errno 111] Connection refused

During handling of the above exception, another exception occurred:

Traceback (most recent call last):
  File "apps/frappe/frappe/utils/scheduler.py", line 75, in enqueue_events_for_site
    if is_scheduler_inactive():
  File "apps/frappe/frappe/utils/scheduler.py", line 114, in is_scheduler_inactive
    if is_scheduler_disabled(verbose=verbose):
  File "apps/frappe/frappe/utils/scheduler.py", line 127, in is_scheduler_disabled
    frappe.db.get_single_value("System Settings", "enable_scheduler")
  File "apps/frappe/frappe/database/database.py", line 786, in get_single_value
    ).run()
  File "apps/frappe/frappe/query_builder/utils.py", line 87, in execute_query
    result = frappe.db.sql(query, params, *args, **kwargs)  # nosemgrep
  File "apps/frappe/frappe/database/database.py", line 201, in sql
    self.connect()
  File "apps/frappe/frappe/database/database.py", line 115, in connect
    self._conn = self.get_connection()
  File "apps/frappe/frappe/database/mariadb/database.py", line 98, in get_connection
    conn = self._get_connection()
  File "apps/frappe/frappe/database/mariadb/database.py", line 104, in _get_connection
    return self.create_connection()
  File "apps/frappe/frappe/database/mariadb/database.py", line 107, in create_connection
    return pymysql.connect(**self.get_connection_settings())
  File "env/lib/python3.10/site-packages/pymysql/connections.py", line 352, in __init__
    self.connect()
  File "env/lib/python3.10/site-packages/pymysql/connections.py", line 668, in connect
    raise exc
pymysql.err.OperationalError: (2003, "Can't connect to MySQL server on '127.0.0.1' ([Errno 111] Connection refused)")

2023-09-15 16:53:09,875 ERROR scheduler Exception in Enqueue Events for Site taskerpage.com
Traceback (most recent call last):
  File "env/lib/python3.10/site-packages/pymysql/connections.py", line 616, in connect
    sock = socket.create_connection(
  File "/usr/lib/python3.10/socket.py", line 845, in create_connection
    raise err
  File "/usr/lib/python3.10/socket.py", line 833, in create_connection
    sock.connect(sa)
ConnectionRefusedError: [Errno 111] Connection refused

During handling of the above exception, another exception occurred:

Traceback (most recent call last):
  File "apps/frappe/frappe/utils/scheduler.py", line 75, in enqueue_events_for_site
    if is_scheduler_inactive():
  File "apps/frappe/frappe/utils/scheduler.py", line 114, in is_scheduler_inactive
    if is_scheduler_disabled(verbose=verbose):
  File "apps/frappe/frappe/utils/scheduler.py", line 127, in is_scheduler_disabled
    frappe.db.get_single_value("System Settings", "enable_scheduler")
  File "apps/frappe/frappe/database/database.py", line 786, in get_single_value
    ).run()
  File "apps/frappe/frappe/query_builder/utils.py", line 87, in execute_query
    result = frappe.db.sql(query, params, *args, **kwargs)  # nosemgrep
  File "apps/frappe/frappe/database/database.py", line 201, in sql
    self.connect()
  File "apps/frappe/frappe/database/database.py", line 115, in connect
    self._conn = self.get_connection()
  File "apps/frappe/frappe/database/mariadb/database.py", line 98, in get_connection
    conn = self._get_connection()
  File "apps/frappe/frappe/database/mariadb/database.py", line 104, in _get_connection
    return self.create_connection()
  File "apps/frappe/frappe/database/mariadb/database.py", line 107, in create_connection
    return pymysql.connect(**self.get_connection_settings())
  File "env/lib/python3.10/site-packages/pymysql/connections.py", line 352, in __init__
    self.connect()
  File "env/lib/python3.10/site-packages/pymysql/connections.py", line 668, in connect
    raise exc
pymysql.err.OperationalError: (2003, "Can't connect to MySQL server on '127.0.0.1' ([Errno 111] Connection refused)")

2023-09-15 16:54:09,981 ERROR scheduler Exception in Enqueue Events for Site taskerpage.com
Traceback (most recent call last):
  File "env/lib/python3.10/site-packages/pymysql/connections.py", line 616, in connect
    sock = socket.create_connection(
  File "/usr/lib/python3.10/socket.py", line 845, in create_connection
    raise err
  File "/usr/lib/python3.10/socket.py", line 833, in create_connection
    sock.connect(sa)
ConnectionRefusedError: [Errno 111] Connection refused

During handling of the above exception, another exception occurred:

Traceback (most recent call last):
  File "apps/frappe/frappe/utils/scheduler.py", line 75, in enqueue_events_for_site
    if is_scheduler_inactive():
  File "apps/frappe/frappe/utils/scheduler.py", line 114, in is_scheduler_inactive
    if is_scheduler_disabled(verbose=verbose):
  File "apps/frappe/frappe/utils/scheduler.py", line 127, in is_scheduler_disabled
    frappe.db.get_single_value("System Settings", "enable_scheduler")
  File "apps/frappe/frappe/database/database.py", line 786, in get_single_value
    ).run()
  File "apps/frappe/frappe/query_builder/utils.py", line 87, in execute_query
    result = frappe.db.sql(query, params, *args, **kwargs)  # nosemgrep
  File "apps/frappe/frappe/database/database.py", line 201, in sql
    self.connect()
  File "apps/frappe/frappe/database/database.py", line 115, in connect
    self._conn = self.get_connection()
  File "apps/frappe/frappe/database/mariadb/database.py", line 98, in get_connection
    conn = self._get_connection()
  File "apps/frappe/frappe/database/mariadb/database.py", line 104, in _get_connection
    return self.create_connection()
  File "apps/frappe/frappe/database/mariadb/database.py", line 107, in create_connection
    return pymysql.connect(**self.get_connection_settings())
  File "env/lib/python3.10/site-packages/pymysql/connections.py", line 352, in __init__
    self.connect()
  File "env/lib/python3.10/site-packages/pymysql/connections.py", line 668, in connect
    raise exc
pymysql.err.OperationalError: (2003, "Can't connect to MySQL server on '127.0.0.1' ([Errno 111] Connection refused)")

2023-09-15 16:55:10,079 ERROR scheduler Exception in Enqueue Events for Site taskerpage.com
Traceback (most recent call last):
  File "env/lib/python3.10/site-packages/pymysql/connections.py", line 616, in connect
    sock = socket.create_connection(
  File "/usr/lib/python3.10/socket.py", line 845, in create_connection
    raise err
  File "/usr/lib/python3.10/socket.py", line 833, in create_connection
    sock.connect(sa)
ConnectionRefusedError: [Errno 111] Connection refused

During handling of the above exception, another exception occurred:

Traceback (most recent call last):
  File "apps/frappe/frappe/utils/scheduler.py", line 75, in enqueue_events_for_site
    if is_scheduler_inactive():
  File "apps/frappe/frappe/utils/scheduler.py", line 114, in is_scheduler_inactive
    if is_scheduler_disabled(verbose=verbose):
  File "apps/frappe/frappe/utils/scheduler.py", line 127, in is_scheduler_disabled
    frappe.db.get_single_value("System Settings", "enable_scheduler")
  File "apps/frappe/frappe/database/database.py", line 786, in get_single_value
    ).run()
  File "apps/frappe/frappe/query_builder/utils.py", line 87, in execute_query
    result = frappe.db.sql(query, params, *args, **kwargs)  # nosemgrep
  File "apps/frappe/frappe/database/database.py", line 201, in sql
    self.connect()
  File "apps/frappe/frappe/database/database.py", line 115, in connect
    self._conn = self.get_connection()
  File "apps/frappe/frappe/database/mariadb/database.py", line 98, in get_connection
    conn = self._get_connection()
  File "apps/frappe/frappe/database/mariadb/database.py", line 104, in _get_connection
    return self.create_connection()
  File "apps/frappe/frappe/database/mariadb/database.py", line 107, in create_connection
    return pymysql.connect(**self.get_connection_settings())
  File "env/lib/python3.10/site-packages/pymysql/connections.py", line 352, in __init__
    self.connect()
  File "env/lib/python3.10/site-packages/pymysql/connections.py", line 668, in connect
    raise exc
pymysql.err.OperationalError: (2003, "Can't connect to MySQL server on '127.0.0.1' ([Errno 111] Connection refused)")

2023-09-15 16:56:10,161 ERROR scheduler Exception in Enqueue Events for Site taskerpage.com
Traceback (most recent call last):
  File "env/lib/python3.10/site-packages/pymysql/connections.py", line 616, in connect
    sock = socket.create_connection(
  File "/usr/lib/python3.10/socket.py", line 845, in create_connection
    raise err
  File "/usr/lib/python3.10/socket.py", line 833, in create_connection
    sock.connect(sa)
ConnectionRefusedError: [Errno 111] Connection refused

During handling of the above exception, another exception occurred:

Traceback (most recent call last):
  File "apps/frappe/frappe/utils/scheduler.py", line 75, in enqueue_events_for_site
    if is_scheduler_inactive():
  File "apps/frappe/frappe/utils/scheduler.py", line 114, in is_scheduler_inactive
    if is_scheduler_disabled(verbose=verbose):
  File "apps/frappe/frappe/utils/scheduler.py", line 127, in is_scheduler_disabled
    frappe.db.get_single_value("System Settings", "enable_scheduler")
  File "apps/frappe/frappe/database/database.py", line 786, in get_single_value
    ).run()
  File "apps/frappe/frappe/query_builder/utils.py", line 87, in execute_query
    result = frappe.db.sql(query, params, *args, **kwargs)  # nosemgrep
  File "apps/frappe/frappe/database/database.py", line 201, in sql
    self.connect()
  File "apps/frappe/frappe/database/database.py", line 115, in connect
    self._conn = self.get_connection()
  File "apps/frappe/frappe/database/mariadb/database.py", line 98, in get_connection
    conn = self._get_connection()
  File "apps/frappe/frappe/database/mariadb/database.py", line 104, in _get_connection
    return self.create_connection()
  File "apps/frappe/frappe/database/mariadb/database.py", line 107, in create_connection
    return pymysql.connect(**self.get_connection_settings())
  File "env/lib/python3.10/site-packages/pymysql/connections.py", line 352, in __init__
    self.connect()
  File "env/lib/python3.10/site-packages/pymysql/connections.py", line 668, in connect
    raise exc
pymysql.err.OperationalError: (2003, "Can't connect to MySQL server on '127.0.0.1' ([Errno 111] Connection refused)")

2023-09-15 16:57:10,262 ERROR scheduler Exception in Enqueue Events for Site taskerpage.com
Traceback (most recent call last):
  File "env/lib/python3.10/site-packages/pymysql/connections.py", line 616, in connect
    sock = socket.create_connection(
  File "/usr/lib/python3.10/socket.py", line 845, in create_connection
    raise err
  File "/usr/lib/python3.10/socket.py", line 833, in create_connection
    sock.connect(sa)
ConnectionRefusedError: [Errno 111] Connection refused

During handling of the above exception, another exception occurred:

Traceback (most recent call last):
  File "apps/frappe/frappe/utils/scheduler.py", line 75, in enqueue_events_for_site
    if is_scheduler_inactive():
  File "apps/frappe/frappe/utils/scheduler.py", line 114, in is_scheduler_inactive
    if is_scheduler_disabled(verbose=verbose):
  File "apps/frappe/frappe/utils/scheduler.py", line 127, in is_scheduler_disabled
    frappe.db.get_single_value("System Settings", "enable_scheduler")
  File "apps/frappe/frappe/database/database.py", line 786, in get_single_value
    ).run()
  File "apps/frappe/frappe/query_builder/utils.py", line 87, in execute_query
    result = frappe.db.sql(query, params, *args, **kwargs)  # nosemgrep
  File "apps/frappe/frappe/database/database.py", line 201, in sql
    self.connect()
  File "apps/frappe/frappe/database/database.py", line 115, in connect
    self._conn = self.get_connection()
  File "apps/frappe/frappe/database/mariadb/database.py", line 98, in get_connection
    conn = self._get_connection()
  File "apps/frappe/frappe/database/mariadb/database.py", line 104, in _get_connection
    return self.create_connection()
  File "apps/frappe/frappe/database/mariadb/database.py", line 107, in create_connection
    return pymysql.connect(**self.get_connection_settings())
  File "env/lib/python3.10/site-packages/pymysql/connections.py", line 352, in __init__
    self.connect()
  File "env/lib/python3.10/site-packages/pymysql/connections.py", line 668, in connect
    raise exc
pymysql.err.OperationalError: (2003, "Can't connect to MySQL server on '127.0.0.1' ([Errno 111] Connection refused)")

2023-09-15 16:58:10,368 ERROR scheduler Exception in Enqueue Events for Site taskerpage.com
Traceback (most recent call last):
  File "env/lib/python3.10/site-packages/pymysql/connections.py", line 616, in connect
    sock = socket.create_connection(
  File "/usr/lib/python3.10/socket.py", line 845, in create_connection
    raise err
  File "/usr/lib/python3.10/socket.py", line 833, in create_connection
    sock.connect(sa)
ConnectionRefusedError: [Errno 111] Connection refused

During handling of the above exception, another exception occurred:

Traceback (most recent call last):
  File "apps/frappe/frappe/utils/scheduler.py", line 75, in enqueue_events_for_site
    if is_scheduler_inactive():
  File "apps/frappe/frappe/utils/scheduler.py", line 114, in is_scheduler_inactive
    if is_scheduler_disabled(verbose=verbose):
  File "apps/frappe/frappe/utils/scheduler.py", line 127, in is_scheduler_disabled
    frappe.db.get_single_value("System Settings", "enable_scheduler")
  File "apps/frappe/frappe/database/database.py", line 786, in get_single_value
    ).run()
  File "apps/frappe/frappe/query_builder/utils.py", line 87, in execute_query
    result = frappe.db.sql(query, params, *args, **kwargs)  # nosemgrep
  File "apps/frappe/frappe/database/database.py", line 201, in sql
    self.connect()
  File "apps/frappe/frappe/database/database.py", line 115, in connect
    self._conn = self.get_connection()
  File "apps/frappe/frappe/database/mariadb/database.py", line 98, in get_connection
    conn = self._get_connection()
  File "apps/frappe/frappe/database/mariadb/database.py", line 104, in _get_connection
    return self.create_connection()
  File "apps/frappe/frappe/database/mariadb/database.py", line 107, in create_connection
    return pymysql.connect(**self.get_connection_settings())
  File "env/lib/python3.10/site-packages/pymysql/connections.py", line 352, in __init__
    self.connect()
  File "env/lib/python3.10/site-packages/pymysql/connections.py", line 668, in connect
    raise exc
pymysql.err.OperationalError: (2003, "Can't connect to MySQL server on '127.0.0.1' ([Errno 111] Connection refused)")

2023-09-15 16:59:10,462 ERROR scheduler Exception in Enqueue Events for Site taskerpage.com
Traceback (most recent call last):
  File "env/lib/python3.10/site-packages/pymysql/connections.py", line 616, in connect
    sock = socket.create_connection(
  File "/usr/lib/python3.10/socket.py", line 845, in create_connection
    raise err
  File "/usr/lib/python3.10/socket.py", line 833, in create_connection
    sock.connect(sa)
ConnectionRefusedError: [Errno 111] Connection refused

During handling of the above exception, another exception occurred:

Traceback (most recent call last):
  File "apps/frappe/frappe/utils/scheduler.py", line 75, in enqueue_events_for_site
    if is_scheduler_inactive():
  File "apps/frappe/frappe/utils/scheduler.py", line 114, in is_scheduler_inactive
    if is_scheduler_disabled(verbose=verbose):
  File "apps/frappe/frappe/utils/scheduler.py", line 127, in is_scheduler_disabled
    frappe.db.get_single_value("System Settings", "enable_scheduler")
  File "apps/frappe/frappe/database/database.py", line 786, in get_single_value
    ).run()
  File "apps/frappe/frappe/query_builder/utils.py", line 87, in execute_query
    result = frappe.db.sql(query, params, *args, **kwargs)  # nosemgrep
  File "apps/frappe/frappe/database/database.py", line 201, in sql
    self.connect()
  File "apps/frappe/frappe/database/database.py", line 115, in connect
    self._conn = self.get_connection()
  File "apps/frappe/frappe/database/mariadb/database.py", line 98, in get_connection
    conn = self._get_connection()
  File "apps/frappe/frappe/database/mariadb/database.py", line 104, in _get_connection
    return self.create_connection()
  File "apps/frappe/frappe/database/mariadb/database.py", line 107, in create_connection
    return pymysql.connect(**self.get_connection_settings())
  File "env/lib/python3.10/site-packages/pymysql/connections.py", line 352, in __init__
    self.connect()
  File "env/lib/python3.10/site-packages/pymysql/connections.py", line 668, in connect
    raise exc
pymysql.err.OperationalError: (2003, "Can't connect to MySQL server on '127.0.0.1' ([Errno 111] Connection refused)")

2023-09-15 17:00:10,568 ERROR scheduler Exception in Enqueue Events for Site taskerpage.com
Traceback (most recent call last):
  File "env/lib/python3.10/site-packages/pymysql/connections.py", line 616, in connect
    sock = socket.create_connection(
  File "/usr/lib/python3.10/socket.py", line 845, in create_connection
    raise err
  File "/usr/lib/python3.10/socket.py", line 833, in create_connection
    sock.connect(sa)
ConnectionRefusedError: [Errno 111] Connection refused

During handling of the above exception, another exception occurred:

Traceback (most recent call last):
  File "apps/frappe/frappe/utils/scheduler.py", line 75, in enqueue_events_for_site
    if is_scheduler_inactive():
  File "apps/frappe/frappe/utils/scheduler.py", line 114, in is_scheduler_inactive
    if is_scheduler_disabled(verbose=verbose):
  File "apps/frappe/frappe/utils/scheduler.py", line 127, in is_scheduler_disabled
    frappe.db.get_single_value("System Settings", "enable_scheduler")
  File "apps/frappe/frappe/database/database.py", line 786, in get_single_value
    ).run()
  File "apps/frappe/frappe/query_builder/utils.py", line 87, in execute_query
    result = frappe.db.sql(query, params, *args, **kwargs)  # nosemgrep
  File "apps/frappe/frappe/database/database.py", line 201, in sql
    self.connect()
  File "apps/frappe/frappe/database/database.py", line 115, in connect
    self._conn = self.get_connection()
  File "apps/frappe/frappe/database/mariadb/database.py", line 98, in get_connection
    conn = self._get_connection()
  File "apps/frappe/frappe/database/mariadb/database.py", line 104, in _get_connection
    return self.create_connection()
  File "apps/frappe/frappe/database/mariadb/database.py", line 107, in create_connection
    return pymysql.connect(**self.get_connection_settings())
  File "env/lib/python3.10/site-packages/pymysql/connections.py", line 352, in __init__
    self.connect()
  File "env/lib/python3.10/site-packages/pymysql/connections.py", line 668, in connect
    raise exc
pymysql.err.OperationalError: (2003, "Can't connect to MySQL server on '127.0.0.1' ([Errno 111] Connection refused)")

2023-09-15 17:01:10,657 ERROR scheduler Exception in Enqueue Events for Site taskerpage.com
Traceback (most recent call last):
  File "env/lib/python3.10/site-packages/pymysql/connections.py", line 616, in connect
    sock = socket.create_connection(
  File "/usr/lib/python3.10/socket.py", line 845, in create_connection
    raise err
  File "/usr/lib/python3.10/socket.py", line 833, in create_connection
    sock.connect(sa)
ConnectionRefusedError: [Errno 111] Connection refused

During handling of the above exception, another exception occurred:

Traceback (most recent call last):
  File "apps/frappe/frappe/utils/scheduler.py", line 75, in enqueue_events_for_site
    if is_scheduler_inactive():
  File "apps/frappe/frappe/utils/scheduler.py", line 114, in is_scheduler_inactive
    if is_scheduler_disabled(verbose=verbose):
  File "apps/frappe/frappe/utils/scheduler.py", line 127, in is_scheduler_disabled
    frappe.db.get_single_value("System Settings", "enable_scheduler")
  File "apps/frappe/frappe/database/database.py", line 786, in get_single_value
    ).run()
  File "apps/frappe/frappe/query_builder/utils.py", line 87, in execute_query
    result = frappe.db.sql(query, params, *args, **kwargs)  # nosemgrep
  File "apps/frappe/frappe/database/database.py", line 201, in sql
    self.connect()
  File "apps/frappe/frappe/database/database.py", line 115, in connect
    self._conn = self.get_connection()
  File "apps/frappe/frappe/database/mariadb/database.py", line 98, in get_connection
    conn = self._get_connection()
  File "apps/frappe/frappe/database/mariadb/database.py", line 104, in _get_connection
    return self.create_connection()
  File "apps/frappe/frappe/database/mariadb/database.py", line 107, in create_connection
    return pymysql.connect(**self.get_connection_settings())
  File "env/lib/python3.10/site-packages/pymysql/connections.py", line 352, in __init__
    self.connect()
  File "env/lib/python3.10/site-packages/pymysql/connections.py", line 668, in connect
    raise exc
pymysql.err.OperationalError: (2003, "Can't connect to MySQL server on '127.0.0.1' ([Errno 111] Connection refused)")

2023-09-15 17:02:10,751 ERROR scheduler Exception in Enqueue Events for Site taskerpage.com
Traceback (most recent call last):
  File "env/lib/python3.10/site-packages/pymysql/connections.py", line 616, in connect
    sock = socket.create_connection(
  File "/usr/lib/python3.10/socket.py", line 845, in create_connection
    raise err
  File "/usr/lib/python3.10/socket.py", line 833, in create_connection
    sock.connect(sa)
ConnectionRefusedError: [Errno 111] Connection refused

During handling of the above exception, another exception occurred:

Traceback (most recent call last):
  File "apps/frappe/frappe/utils/scheduler.py", line 75, in enqueue_events_for_site
    if is_scheduler_inactive():
  File "apps/frappe/frappe/utils/scheduler.py", line 114, in is_scheduler_inactive
    if is_scheduler_disabled(verbose=verbose):
  File "apps/frappe/frappe/utils/scheduler.py", line 127, in is_scheduler_disabled
    frappe.db.get_single_value("System Settings", "enable_scheduler")
  File "apps/frappe/frappe/database/database.py", line 786, in get_single_value
    ).run()
  File "apps/frappe/frappe/query_builder/utils.py", line 87, in execute_query
    result = frappe.db.sql(query, params, *args, **kwargs)  # nosemgrep
  File "apps/frappe/frappe/database/database.py", line 201, in sql
    self.connect()
  File "apps/frappe/frappe/database/database.py", line 115, in connect
    self._conn = self.get_connection()
  File "apps/frappe/frappe/database/mariadb/database.py", line 98, in get_connection
    conn = self._get_connection()
  File "apps/frappe/frappe/database/mariadb/database.py", line 104, in _get_connection
    return self.create_connection()
  File "apps/frappe/frappe/database/mariadb/database.py", line 107, in create_connection
    return pymysql.connect(**self.get_connection_settings())
  File "env/lib/python3.10/site-packages/pymysql/connections.py", line 352, in __init__
    self.connect()
  File "env/lib/python3.10/site-packages/pymysql/connections.py", line 668, in connect
    raise exc
pymysql.err.OperationalError: (2003, "Can't connect to MySQL server on '127.0.0.1' ([Errno 111] Connection refused)")

2023-09-15 17:03:10,844 ERROR scheduler Exception in Enqueue Events for Site taskerpage.com
Traceback (most recent call last):
  File "env/lib/python3.10/site-packages/pymysql/connections.py", line 616, in connect
    sock = socket.create_connection(
  File "/usr/lib/python3.10/socket.py", line 845, in create_connection
    raise err
  File "/usr/lib/python3.10/socket.py", line 833, in create_connection
    sock.connect(sa)
ConnectionRefusedError: [Errno 111] Connection refused

During handling of the above exception, another exception occurred:

Traceback (most recent call last):
  File "apps/frappe/frappe/utils/scheduler.py", line 75, in enqueue_events_for_site
    if is_scheduler_inactive():
  File "apps/frappe/frappe/utils/scheduler.py", line 114, in is_scheduler_inactive
    if is_scheduler_disabled(verbose=verbose):
  File "apps/frappe/frappe/utils/scheduler.py", line 127, in is_scheduler_disabled
    frappe.db.get_single_value("System Settings", "enable_scheduler")
  File "apps/frappe/frappe/database/database.py", line 786, in get_single_value
    ).run()
  File "apps/frappe/frappe/query_builder/utils.py", line 87, in execute_query
    result = frappe.db.sql(query, params, *args, **kwargs)  # nosemgrep
  File "apps/frappe/frappe/database/database.py", line 201, in sql
    self.connect()
  File "apps/frappe/frappe/database/database.py", line 115, in connect
    self._conn = self.get_connection()
  File "apps/frappe/frappe/database/mariadb/database.py", line 98, in get_connection
    conn = self._get_connection()
  File "apps/frappe/frappe/database/mariadb/database.py", line 104, in _get_connection
    return self.create_connection()
  File "apps/frappe/frappe/database/mariadb/database.py", line 107, in create_connection
    return pymysql.connect(**self.get_connection_settings())
  File "env/lib/python3.10/site-packages/pymysql/connections.py", line 352, in __init__
    self.connect()
  File "env/lib/python3.10/site-packages/pymysql/connections.py", line 668, in connect
    raise exc
pymysql.err.OperationalError: (2003, "Can't connect to MySQL server on '127.0.0.1' ([Errno 111] Connection refused)")

2023-09-15 17:04:10,938 ERROR scheduler Exception in Enqueue Events for Site taskerpage.com
Traceback (most recent call last):
  File "env/lib/python3.10/site-packages/pymysql/connections.py", line 616, in connect
    sock = socket.create_connection(
  File "/usr/lib/python3.10/socket.py", line 845, in create_connection
    raise err
  File "/usr/lib/python3.10/socket.py", line 833, in create_connection
    sock.connect(sa)
ConnectionRefusedError: [Errno 111] Connection refused

During handling of the above exception, another exception occurred:

Traceback (most recent call last):
  File "apps/frappe/frappe/utils/scheduler.py", line 75, in enqueue_events_for_site
    if is_scheduler_inactive():
  File "apps/frappe/frappe/utils/scheduler.py", line 114, in is_scheduler_inactive
    if is_scheduler_disabled(verbose=verbose):
  File "apps/frappe/frappe/utils/scheduler.py", line 127, in is_scheduler_disabled
    frappe.db.get_single_value("System Settings", "enable_scheduler")
  File "apps/frappe/frappe/database/database.py", line 786, in get_single_value
    ).run()
  File "apps/frappe/frappe/query_builder/utils.py", line 87, in execute_query
    result = frappe.db.sql(query, params, *args, **kwargs)  # nosemgrep
  File "apps/frappe/frappe/database/database.py", line 201, in sql
    self.connect()
  File "apps/frappe/frappe/database/database.py", line 115, in connect
    self._conn = self.get_connection()
  File "apps/frappe/frappe/database/mariadb/database.py", line 98, in get_connection
    conn = self._get_connection()
  File "apps/frappe/frappe/database/mariadb/database.py", line 104, in _get_connection
    return self.create_connection()
  File "apps/frappe/frappe/database/mariadb/database.py", line 107, in create_connection
    return pymysql.connect(**self.get_connection_settings())
  File "env/lib/python3.10/site-packages/pymysql/connections.py", line 352, in __init__
    self.connect()
  File "env/lib/python3.10/site-packages/pymysql/connections.py", line 668, in connect
    raise exc
pymysql.err.OperationalError: (2003, "Can't connect to MySQL server on '127.0.0.1' ([Errno 111] Connection refused)")

2023-09-15 17:05:10,948 ERROR scheduler Exception in Enqueue Events for Site taskerpage.com
Traceback (most recent call last):
  File "env/lib/python3.10/site-packages/pymysql/connections.py", line 616, in connect
    sock = socket.create_connection(
  File "/usr/lib/python3.10/socket.py", line 845, in create_connection
    raise err
  File "/usr/lib/python3.10/socket.py", line 833, in create_connection
    sock.connect(sa)
ConnectionRefusedError: [Errno 111] Connection refused

During handling of the above exception, another exception occurred:

Traceback (most recent call last):
  File "apps/frappe/frappe/utils/scheduler.py", line 75, in enqueue_events_for_site
    if is_scheduler_inactive():
  File "apps/frappe/frappe/utils/scheduler.py", line 114, in is_scheduler_inactive
    if is_scheduler_disabled(verbose=verbose):
  File "apps/frappe/frappe/utils/scheduler.py", line 127, in is_scheduler_disabled
    frappe.db.get_single_value("System Settings", "enable_scheduler")
  File "apps/frappe/frappe/database/database.py", line 786, in get_single_value
    ).run()
  File "apps/frappe/frappe/query_builder/utils.py", line 87, in execute_query
    result = frappe.db.sql(query, params, *args, **kwargs)  # nosemgrep
  File "apps/frappe/frappe/database/database.py", line 201, in sql
    self.connect()
  File "apps/frappe/frappe/database/database.py", line 115, in connect
    self._conn = self.get_connection()
  File "apps/frappe/frappe/database/mariadb/database.py", line 98, in get_connection
    conn = self._get_connection()
  File "apps/frappe/frappe/database/mariadb/database.py", line 104, in _get_connection
    return self.create_connection()
  File "apps/frappe/frappe/database/mariadb/database.py", line 107, in create_connection
    return pymysql.connect(**self.get_connection_settings())
  File "env/lib/python3.10/site-packages/pymysql/connections.py", line 352, in __init__
    self.connect()
  File "env/lib/python3.10/site-packages/pymysql/connections.py", line 668, in connect
    raise exc
pymysql.err.OperationalError: (2003, "Can't connect to MySQL server on '127.0.0.1' ([Errno 111] Connection refused)")

2023-09-15 17:06:11,023 ERROR scheduler Exception in Enqueue Events for Site taskerpage.com
Traceback (most recent call last):
  File "env/lib/python3.10/site-packages/pymysql/connections.py", line 616, in connect
    sock = socket.create_connection(
  File "/usr/lib/python3.10/socket.py", line 845, in create_connection
    raise err
  File "/usr/lib/python3.10/socket.py", line 833, in create_connection
    sock.connect(sa)
ConnectionRefusedError: [Errno 111] Connection refused

During handling of the above exception, another exception occurred:

Traceback (most recent call last):
  File "apps/frappe/frappe/utils/scheduler.py", line 75, in enqueue_events_for_site
    if is_scheduler_inactive():
  File "apps/frappe/frappe/utils/scheduler.py", line 114, in is_scheduler_inactive
    if is_scheduler_disabled(verbose=verbose):
  File "apps/frappe/frappe/utils/scheduler.py", line 127, in is_scheduler_disabled
    frappe.db.get_single_value("System Settings", "enable_scheduler")
  File "apps/frappe/frappe/database/database.py", line 786, in get_single_value
    ).run()
  File "apps/frappe/frappe/query_builder/utils.py", line 87, in execute_query
    result = frappe.db.sql(query, params, *args, **kwargs)  # nosemgrep
  File "apps/frappe/frappe/database/database.py", line 201, in sql
    self.connect()
  File "apps/frappe/frappe/database/database.py", line 115, in connect
    self._conn = self.get_connection()
  File "apps/frappe/frappe/database/mariadb/database.py", line 98, in get_connection
    conn = self._get_connection()
  File "apps/frappe/frappe/database/mariadb/database.py", line 104, in _get_connection
    return self.create_connection()
  File "apps/frappe/frappe/database/mariadb/database.py", line 107, in create_connection
    return pymysql.connect(**self.get_connection_settings())
  File "env/lib/python3.10/site-packages/pymysql/connections.py", line 352, in __init__
    self.connect()
  File "env/lib/python3.10/site-packages/pymysql/connections.py", line 668, in connect
    raise exc
pymysql.err.OperationalError: (2003, "Can't connect to MySQL server on '127.0.0.1' ([Errno 111] Connection refused)")

2023-09-15 17:07:11,099 ERROR scheduler Exception in Enqueue Events for Site taskerpage.com
Traceback (most recent call last):
  File "env/lib/python3.10/site-packages/pymysql/connections.py", line 616, in connect
    sock = socket.create_connection(
  File "/usr/lib/python3.10/socket.py", line 845, in create_connection
    raise err
  File "/usr/lib/python3.10/socket.py", line 833, in create_connection
    sock.connect(sa)
ConnectionRefusedError: [Errno 111] Connection refused

During handling of the above exception, another exception occurred:

Traceback (most recent call last):
  File "apps/frappe/frappe/utils/scheduler.py", line 75, in enqueue_events_for_site
    if is_scheduler_inactive():
  File "apps/frappe/frappe/utils/scheduler.py", line 114, in is_scheduler_inactive
    if is_scheduler_disabled(verbose=verbose):
  File "apps/frappe/frappe/utils/scheduler.py", line 127, in is_scheduler_disabled
    frappe.db.get_single_value("System Settings", "enable_scheduler")
  File "apps/frappe/frappe/database/database.py", line 786, in get_single_value
    ).run()
  File "apps/frappe/frappe/query_builder/utils.py", line 87, in execute_query
    result = frappe.db.sql(query, params, *args, **kwargs)  # nosemgrep
  File "apps/frappe/frappe/database/database.py", line 201, in sql
    self.connect()
  File "apps/frappe/frappe/database/database.py", line 115, in connect
    self._conn = self.get_connection()
  File "apps/frappe/frappe/database/mariadb/database.py", line 98, in get_connection
    conn = self._get_connection()
  File "apps/frappe/frappe/database/mariadb/database.py", line 104, in _get_connection
    return self.create_connection()
  File "apps/frappe/frappe/database/mariadb/database.py", line 107, in create_connection
    return pymysql.connect(**self.get_connection_settings())
  File "env/lib/python3.10/site-packages/pymysql/connections.py", line 352, in __init__
    self.connect()
  File "env/lib/python3.10/site-packages/pymysql/connections.py", line 668, in connect
    raise exc
pymysql.err.OperationalError: (2003, "Can't connect to MySQL server on '127.0.0.1' ([Errno 111] Connection refused)")

2023-09-15 17:08:11,208 ERROR scheduler Exception in Enqueue Events for Site taskerpage.com
Traceback (most recent call last):
  File "env/lib/python3.10/site-packages/pymysql/connections.py", line 616, in connect
    sock = socket.create_connection(
  File "/usr/lib/python3.10/socket.py", line 845, in create_connection
    raise err
  File "/usr/lib/python3.10/socket.py", line 833, in create_connection
    sock.connect(sa)
ConnectionRefusedError: [Errno 111] Connection refused

During handling of the above exception, another exception occurred:

Traceback (most recent call last):
  File "apps/frappe/frappe/utils/scheduler.py", line 75, in enqueue_events_for_site
    if is_scheduler_inactive():
  File "apps/frappe/frappe/utils/scheduler.py", line 114, in is_scheduler_inactive
    if is_scheduler_disabled(verbose=verbose):
  File "apps/frappe/frappe/utils/scheduler.py", line 127, in is_scheduler_disabled
    frappe.db.get_single_value("System Settings", "enable_scheduler")
  File "apps/frappe/frappe/database/database.py", line 786, in get_single_value
    ).run()
  File "apps/frappe/frappe/query_builder/utils.py", line 87, in execute_query
    result = frappe.db.sql(query, params, *args, **kwargs)  # nosemgrep
  File "apps/frappe/frappe/database/database.py", line 201, in sql
    self.connect()
  File "apps/frappe/frappe/database/database.py", line 115, in connect
    self._conn = self.get_connection()
  File "apps/frappe/frappe/database/mariadb/database.py", line 98, in get_connection
    conn = self._get_connection()
  File "apps/frappe/frappe/database/mariadb/database.py", line 104, in _get_connection
    return self.create_connection()
  File "apps/frappe/frappe/database/mariadb/database.py", line 107, in create_connection
    return pymysql.connect(**self.get_connection_settings())
  File "env/lib/python3.10/site-packages/pymysql/connections.py", line 352, in __init__
    self.connect()
  File "env/lib/python3.10/site-packages/pymysql/connections.py", line 668, in connect
    raise exc
pymysql.err.OperationalError: (2003, "Can't connect to MySQL server on '127.0.0.1' ([Errno 111] Connection refused)")

2023-09-15 17:09:11,313 ERROR scheduler Exception in Enqueue Events for Site taskerpage.com
Traceback (most recent call last):
  File "env/lib/python3.10/site-packages/pymysql/connections.py", line 616, in connect
    sock = socket.create_connection(
  File "/usr/lib/python3.10/socket.py", line 845, in create_connection
    raise err
  File "/usr/lib/python3.10/socket.py", line 833, in create_connection
    sock.connect(sa)
ConnectionRefusedError: [Errno 111] Connection refused

During handling of the above exception, another exception occurred:

Traceback (most recent call last):
  File "apps/frappe/frappe/utils/scheduler.py", line 75, in enqueue_events_for_site
    if is_scheduler_inactive():
  File "apps/frappe/frappe/utils/scheduler.py", line 114, in is_scheduler_inactive
    if is_scheduler_disabled(verbose=verbose):
  File "apps/frappe/frappe/utils/scheduler.py", line 127, in is_scheduler_disabled
    frappe.db.get_single_value("System Settings", "enable_scheduler")
  File "apps/frappe/frappe/database/database.py", line 786, in get_single_value
    ).run()
  File "apps/frappe/frappe/query_builder/utils.py", line 87, in execute_query
    result = frappe.db.sql(query, params, *args, **kwargs)  # nosemgrep
  File "apps/frappe/frappe/database/database.py", line 201, in sql
    self.connect()
  File "apps/frappe/frappe/database/database.py", line 115, in connect
    self._conn = self.get_connection()
  File "apps/frappe/frappe/database/mariadb/database.py", line 98, in get_connection
    conn = self._get_connection()
  File "apps/frappe/frappe/database/mariadb/database.py", line 104, in _get_connection
    return self.create_connection()
  File "apps/frappe/frappe/database/mariadb/database.py", line 107, in create_connection
    return pymysql.connect(**self.get_connection_settings())
  File "env/lib/python3.10/site-packages/pymysql/connections.py", line 352, in __init__
    self.connect()
  File "env/lib/python3.10/site-packages/pymysql/connections.py", line 668, in connect
    raise exc
pymysql.err.OperationalError: (2003, "Can't connect to MySQL server on '127.0.0.1' ([Errno 111] Connection refused)")

2023-09-15 17:10:11,419 ERROR scheduler Exception in Enqueue Events for Site taskerpage.com
Traceback (most recent call last):
  File "env/lib/python3.10/site-packages/pymysql/connections.py", line 616, in connect
    sock = socket.create_connection(
  File "/usr/lib/python3.10/socket.py", line 845, in create_connection
    raise err
  File "/usr/lib/python3.10/socket.py", line 833, in create_connection
    sock.connect(sa)
ConnectionRefusedError: [Errno 111] Connection refused

During handling of the above exception, another exception occurred:

Traceback (most recent call last):
  File "apps/frappe/frappe/utils/scheduler.py", line 75, in enqueue_events_for_site
    if is_scheduler_inactive():
  File "apps/frappe/frappe/utils/scheduler.py", line 114, in is_scheduler_inactive
    if is_scheduler_disabled(verbose=verbose):
  File "apps/frappe/frappe/utils/scheduler.py", line 127, in is_scheduler_disabled
    frappe.db.get_single_value("System Settings", "enable_scheduler")
  File "apps/frappe/frappe/database/database.py", line 786, in get_single_value
    ).run()
  File "apps/frappe/frappe/query_builder/utils.py", line 87, in execute_query
    result = frappe.db.sql(query, params, *args, **kwargs)  # nosemgrep
  File "apps/frappe/frappe/database/database.py", line 201, in sql
    self.connect()
  File "apps/frappe/frappe/database/database.py", line 115, in connect
    self._conn = self.get_connection()
  File "apps/frappe/frappe/database/mariadb/database.py", line 98, in get_connection
    conn = self._get_connection()
  File "apps/frappe/frappe/database/mariadb/database.py", line 104, in _get_connection
    return self.create_connection()
  File "apps/frappe/frappe/database/mariadb/database.py", line 107, in create_connection
    return pymysql.connect(**self.get_connection_settings())
  File "env/lib/python3.10/site-packages/pymysql/connections.py", line 352, in __init__
    self.connect()
  File "env/lib/python3.10/site-packages/pymysql/connections.py", line 668, in connect
    raise exc
pymysql.err.OperationalError: (2003, "Can't connect to MySQL server on '127.0.0.1' ([Errno 111] Connection refused)")

2023-09-15 17:11:11,523 ERROR scheduler Exception in Enqueue Events for Site taskerpage.com
Traceback (most recent call last):
  File "env/lib/python3.10/site-packages/pymysql/connections.py", line 616, in connect
    sock = socket.create_connection(
  File "/usr/lib/python3.10/socket.py", line 845, in create_connection
    raise err
  File "/usr/lib/python3.10/socket.py", line 833, in create_connection
    sock.connect(sa)
ConnectionRefusedError: [Errno 111] Connection refused

During handling of the above exception, another exception occurred:

Traceback (most recent call last):
  File "apps/frappe/frappe/utils/scheduler.py", line 75, in enqueue_events_for_site
    if is_scheduler_inactive():
  File "apps/frappe/frappe/utils/scheduler.py", line 114, in is_scheduler_inactive
    if is_scheduler_disabled(verbose=verbose):
  File "apps/frappe/frappe/utils/scheduler.py", line 127, in is_scheduler_disabled
    frappe.db.get_single_value("System Settings", "enable_scheduler")
  File "apps/frappe/frappe/database/database.py", line 786, in get_single_value
    ).run()
  File "apps/frappe/frappe/query_builder/utils.py", line 87, in execute_query
    result = frappe.db.sql(query, params, *args, **kwargs)  # nosemgrep
  File "apps/frappe/frappe/database/database.py", line 201, in sql
    self.connect()
  File "apps/frappe/frappe/database/database.py", line 115, in connect
    self._conn = self.get_connection()
  File "apps/frappe/frappe/database/mariadb/database.py", line 98, in get_connection
    conn = self._get_connection()
  File "apps/frappe/frappe/database/mariadb/database.py", line 104, in _get_connection
    return self.create_connection()
  File "apps/frappe/frappe/database/mariadb/database.py", line 107, in create_connection
    return pymysql.connect(**self.get_connection_settings())
  File "env/lib/python3.10/site-packages/pymysql/connections.py", line 352, in __init__
    self.connect()
  File "env/lib/python3.10/site-packages/pymysql/connections.py", line 668, in connect
    raise exc
pymysql.err.OperationalError: (2003, "Can't connect to MySQL server on '127.0.0.1' ([Errno 111] Connection refused)")

2023-09-15 17:12:11,619 ERROR scheduler Exception in Enqueue Events for Site taskerpage.com
Traceback (most recent call last):
  File "env/lib/python3.10/site-packages/pymysql/connections.py", line 616, in connect
    sock = socket.create_connection(
  File "/usr/lib/python3.10/socket.py", line 845, in create_connection
    raise err
  File "/usr/lib/python3.10/socket.py", line 833, in create_connection
    sock.connect(sa)
ConnectionRefusedError: [Errno 111] Connection refused

During handling of the above exception, another exception occurred:

Traceback (most recent call last):
  File "apps/frappe/frappe/utils/scheduler.py", line 75, in enqueue_events_for_site
    if is_scheduler_inactive():
  File "apps/frappe/frappe/utils/scheduler.py", line 114, in is_scheduler_inactive
    if is_scheduler_disabled(verbose=verbose):
  File "apps/frappe/frappe/utils/scheduler.py", line 127, in is_scheduler_disabled
    frappe.db.get_single_value("System Settings", "enable_scheduler")
  File "apps/frappe/frappe/database/database.py", line 786, in get_single_value
    ).run()
  File "apps/frappe/frappe/query_builder/utils.py", line 87, in execute_query
    result = frappe.db.sql(query, params, *args, **kwargs)  # nosemgrep
  File "apps/frappe/frappe/database/database.py", line 201, in sql
    self.connect()
  File "apps/frappe/frappe/database/database.py", line 115, in connect
    self._conn = self.get_connection()
  File "apps/frappe/frappe/database/mariadb/database.py", line 98, in get_connection
    conn = self._get_connection()
  File "apps/frappe/frappe/database/mariadb/database.py", line 104, in _get_connection
    return self.create_connection()
  File "apps/frappe/frappe/database/mariadb/database.py", line 107, in create_connection
    return pymysql.connect(**self.get_connection_settings())
  File "env/lib/python3.10/site-packages/pymysql/connections.py", line 352, in __init__
    self.connect()
  File "env/lib/python3.10/site-packages/pymysql/connections.py", line 668, in connect
    raise exc
pymysql.err.OperationalError: (2003, "Can't connect to MySQL server on '127.0.0.1' ([Errno 111] Connection refused)")

2023-09-15 17:13:11,707 ERROR scheduler Exception in Enqueue Events for Site taskerpage.com
Traceback (most recent call last):
  File "env/lib/python3.10/site-packages/pymysql/connections.py", line 616, in connect
    sock = socket.create_connection(
  File "/usr/lib/python3.10/socket.py", line 845, in create_connection
    raise err
  File "/usr/lib/python3.10/socket.py", line 833, in create_connection
    sock.connect(sa)
ConnectionRefusedError: [Errno 111] Connection refused

During handling of the above exception, another exception occurred:

Traceback (most recent call last):
  File "apps/frappe/frappe/utils/scheduler.py", line 75, in enqueue_events_for_site
    if is_scheduler_inactive():
  File "apps/frappe/frappe/utils/scheduler.py", line 114, in is_scheduler_inactive
    if is_scheduler_disabled(verbose=verbose):
  File "apps/frappe/frappe/utils/scheduler.py", line 127, in is_scheduler_disabled
    frappe.db.get_single_value("System Settings", "enable_scheduler")
  File "apps/frappe/frappe/database/database.py", line 786, in get_single_value
    ).run()
  File "apps/frappe/frappe/query_builder/utils.py", line 87, in execute_query
    result = frappe.db.sql(query, params, *args, **kwargs)  # nosemgrep
  File "apps/frappe/frappe/database/database.py", line 201, in sql
    self.connect()
  File "apps/frappe/frappe/database/database.py", line 115, in connect
    self._conn = self.get_connection()
  File "apps/frappe/frappe/database/mariadb/database.py", line 98, in get_connection
    conn = self._get_connection()
  File "apps/frappe/frappe/database/mariadb/database.py", line 104, in _get_connection
    return self.create_connection()
  File "apps/frappe/frappe/database/mariadb/database.py", line 107, in create_connection
    return pymysql.connect(**self.get_connection_settings())
  File "env/lib/python3.10/site-packages/pymysql/connections.py", line 352, in __init__
    self.connect()
  File "env/lib/python3.10/site-packages/pymysql/connections.py", line 668, in connect
    raise exc
pymysql.err.OperationalError: (2003, "Can't connect to MySQL server on '127.0.0.1' ([Errno 111] Connection refused)")

2023-09-15 17:14:11,812 ERROR scheduler Exception in Enqueue Events for Site taskerpage.com
Traceback (most recent call last):
  File "env/lib/python3.10/site-packages/pymysql/connections.py", line 616, in connect
    sock = socket.create_connection(
  File "/usr/lib/python3.10/socket.py", line 845, in create_connection
    raise err
  File "/usr/lib/python3.10/socket.py", line 833, in create_connection
    sock.connect(sa)
ConnectionRefusedError: [Errno 111] Connection refused

During handling of the above exception, another exception occurred:

Traceback (most recent call last):
  File "apps/frappe/frappe/utils/scheduler.py", line 75, in enqueue_events_for_site
    if is_scheduler_inactive():
  File "apps/frappe/frappe/utils/scheduler.py", line 114, in is_scheduler_inactive
    if is_scheduler_disabled(verbose=verbose):
  File "apps/frappe/frappe/utils/scheduler.py", line 127, in is_scheduler_disabled
    frappe.db.get_single_value("System Settings", "enable_scheduler")
  File "apps/frappe/frappe/database/database.py", line 786, in get_single_value
    ).run()
  File "apps/frappe/frappe/query_builder/utils.py", line 87, in execute_query
    result = frappe.db.sql(query, params, *args, **kwargs)  # nosemgrep
  File "apps/frappe/frappe/database/database.py", line 201, in sql
    self.connect()
  File "apps/frappe/frappe/database/database.py", line 115, in connect
    self._conn = self.get_connection()
  File "apps/frappe/frappe/database/mariadb/database.py", line 98, in get_connection
    conn = self._get_connection()
  File "apps/frappe/frappe/database/mariadb/database.py", line 104, in _get_connection
    return self.create_connection()
  File "apps/frappe/frappe/database/mariadb/database.py", line 107, in create_connection
    return pymysql.connect(**self.get_connection_settings())
  File "env/lib/python3.10/site-packages/pymysql/connections.py", line 352, in __init__
    self.connect()
  File "env/lib/python3.10/site-packages/pymysql/connections.py", line 668, in connect
    raise exc
pymysql.err.OperationalError: (2003, "Can't connect to MySQL server on '127.0.0.1' ([Errno 111] Connection refused)")

2023-09-15 17:15:12,395 ERROR scheduler Exception in Enqueue Events for Site taskerpage.com
Traceback (most recent call last):
  File "env/lib/python3.10/site-packages/pymysql/connections.py", line 616, in connect
    sock = socket.create_connection(
  File "/usr/lib/python3.10/socket.py", line 845, in create_connection
    raise err
  File "/usr/lib/python3.10/socket.py", line 833, in create_connection
    sock.connect(sa)
ConnectionRefusedError: [Errno 111] Connection refused

During handling of the above exception, another exception occurred:

Traceback (most recent call last):
  File "apps/frappe/frappe/utils/scheduler.py", line 75, in enqueue_events_for_site
    if is_scheduler_inactive():
  File "apps/frappe/frappe/utils/scheduler.py", line 114, in is_scheduler_inactive
    if is_scheduler_disabled(verbose=verbose):
  File "apps/frappe/frappe/utils/scheduler.py", line 127, in is_scheduler_disabled
    frappe.db.get_single_value("System Settings", "enable_scheduler")
  File "apps/frappe/frappe/database/database.py", line 786, in get_single_value
    ).run()
  File "apps/frappe/frappe/query_builder/utils.py", line 87, in execute_query
    result = frappe.db.sql(query, params, *args, **kwargs)  # nosemgrep
  File "apps/frappe/frappe/database/database.py", line 201, in sql
    self.connect()
  File "apps/frappe/frappe/database/database.py", line 115, in connect
    self._conn = self.get_connection()
  File "apps/frappe/frappe/database/mariadb/database.py", line 98, in get_connection
    conn = self._get_connection()
  File "apps/frappe/frappe/database/mariadb/database.py", line 104, in _get_connection
    return self.create_connection()
  File "apps/frappe/frappe/database/mariadb/database.py", line 107, in create_connection
    return pymysql.connect(**self.get_connection_settings())
  File "env/lib/python3.10/site-packages/pymysql/connections.py", line 352, in __init__
    self.connect()
  File "env/lib/python3.10/site-packages/pymysql/connections.py", line 668, in connect
    raise exc
pymysql.err.OperationalError: (2003, "Can't connect to MySQL server on '127.0.0.1' ([Errno 111] Connection refused)")

2023-09-15 17:16:12,897 ERROR scheduler Exception in Enqueue Events for Site taskerpage.com
Traceback (most recent call last):
  File "env/lib/python3.10/site-packages/pymysql/connections.py", line 616, in connect
    sock = socket.create_connection(
  File "/usr/lib/python3.10/socket.py", line 845, in create_connection
    raise err
  File "/usr/lib/python3.10/socket.py", line 833, in create_connection
    sock.connect(sa)
ConnectionRefusedError: [Errno 111] Connection refused

During handling of the above exception, another exception occurred:

Traceback (most recent call last):
  File "apps/frappe/frappe/utils/scheduler.py", line 75, in enqueue_events_for_site
    if is_scheduler_inactive():
  File "apps/frappe/frappe/utils/scheduler.py", line 114, in is_scheduler_inactive
    if is_scheduler_disabled(verbose=verbose):
  File "apps/frappe/frappe/utils/scheduler.py", line 127, in is_scheduler_disabled
    frappe.db.get_single_value("System Settings", "enable_scheduler")
  File "apps/frappe/frappe/database/database.py", line 786, in get_single_value
    ).run()
  File "apps/frappe/frappe/query_builder/utils.py", line 87, in execute_query
    result = frappe.db.sql(query, params, *args, **kwargs)  # nosemgrep
  File "apps/frappe/frappe/database/database.py", line 201, in sql
    self.connect()
  File "apps/frappe/frappe/database/database.py", line 115, in connect
    self._conn = self.get_connection()
  File "apps/frappe/frappe/database/mariadb/database.py", line 98, in get_connection
    conn = self._get_connection()
  File "apps/frappe/frappe/database/mariadb/database.py", line 104, in _get_connection
    return self.create_connection()
  File "apps/frappe/frappe/database/mariadb/database.py", line 107, in create_connection
    return pymysql.connect(**self.get_connection_settings())
  File "env/lib/python3.10/site-packages/pymysql/connections.py", line 352, in __init__
    self.connect()
  File "env/lib/python3.10/site-packages/pymysql/connections.py", line 668, in connect
    raise exc
pymysql.err.OperationalError: (2003, "Can't connect to MySQL server on '127.0.0.1' ([Errno 111] Connection refused)")

2023-09-15 17:17:13,020 ERROR scheduler Exception in Enqueue Events for Site taskerpage.com
Traceback (most recent call last):
  File "env/lib/python3.10/site-packages/pymysql/connections.py", line 616, in connect
    sock = socket.create_connection(
  File "/usr/lib/python3.10/socket.py", line 845, in create_connection
    raise err
  File "/usr/lib/python3.10/socket.py", line 833, in create_connection
    sock.connect(sa)
ConnectionRefusedError: [Errno 111] Connection refused

During handling of the above exception, another exception occurred:

Traceback (most recent call last):
  File "apps/frappe/frappe/utils/scheduler.py", line 75, in enqueue_events_for_site
    if is_scheduler_inactive():
  File "apps/frappe/frappe/utils/scheduler.py", line 114, in is_scheduler_inactive
    if is_scheduler_disabled(verbose=verbose):
  File "apps/frappe/frappe/utils/scheduler.py", line 127, in is_scheduler_disabled
    frappe.db.get_single_value("System Settings", "enable_scheduler")
  File "apps/frappe/frappe/database/database.py", line 786, in get_single_value
    ).run()
  File "apps/frappe/frappe/query_builder/utils.py", line 87, in execute_query
    result = frappe.db.sql(query, params, *args, **kwargs)  # nosemgrep
  File "apps/frappe/frappe/database/database.py", line 201, in sql
    self.connect()
  File "apps/frappe/frappe/database/database.py", line 115, in connect
    self._conn = self.get_connection()
  File "apps/frappe/frappe/database/mariadb/database.py", line 98, in get_connection
    conn = self._get_connection()
  File "apps/frappe/frappe/database/mariadb/database.py", line 104, in _get_connection
    return self.create_connection()
  File "apps/frappe/frappe/database/mariadb/database.py", line 107, in create_connection
    return pymysql.connect(**self.get_connection_settings())
  File "env/lib/python3.10/site-packages/pymysql/connections.py", line 352, in __init__
    self.connect()
  File "env/lib/python3.10/site-packages/pymysql/connections.py", line 668, in connect
    raise exc
pymysql.err.OperationalError: (2003, "Can't connect to MySQL server on '127.0.0.1' ([Errno 111] Connection refused)")

2023-09-15 17:19:10,537 ERROR scheduler Exception in Enqueue Events for Site taskerpage.com
Traceback (most recent call last):
  File "apps/frappe/frappe/utils/caching.py", line 55, in wrapper
    return frappe.local.request_cache[func][args_key]
KeyError: 5740354900026072187

During handling of the above exception, another exception occurred:

Traceback (most recent call last):
  File "apps/frappe/frappe/utils/scheduler.py", line 75, in enqueue_events_for_site
    if is_scheduler_inactive():
  File "apps/frappe/frappe/utils/scheduler.py", line 114, in is_scheduler_inactive
    if is_scheduler_disabled(verbose=verbose):
  File "apps/frappe/frappe/utils/scheduler.py", line 127, in is_scheduler_disabled
    frappe.db.get_single_value("System Settings", "enable_scheduler")
  File "apps/frappe/frappe/database/database.py", line 789, in get_single_value
    df = frappe.get_meta(doctype).get_field(fieldname)
  File "apps/frappe/frappe/__init__.py", line 1226, in get_meta
    return frappe.model.meta.get_meta(doctype, cached=cached)
  File "apps/frappe/frappe/model/meta.py", line 65, in get_meta
    meta = Meta(doctype)
  File "apps/frappe/frappe/model/meta.py", line 117, in __init__
    super().__init__("DocType", doctype)
  File "apps/frappe/frappe/model/document.py", line 106, in __init__
    self.load_from_db()
  File "apps/frappe/frappe/model/meta.py", line 123, in load_from_db
    super().load_from_db()
  File "apps/frappe/frappe/model/document.py", line 176, in load_from_db
    self.set(df.fieldname, children)
  File "apps/frappe/frappe/model/base_document.py", line 219, in set
    self.extend(key, value)
  File "apps/frappe/frappe/model/base_document.py", line 260, in extend
    self.append(key, v)
  File "apps/frappe/frappe/model/base_document.py", line 245, in append
    value = self._init_child(value, key)
  File "apps/frappe/frappe/model/base_document.py", line 274, in _init_child
    value = get_controller(doctype)(value)
  File "apps/frappe/frappe/model/base_document.py", line 93, in get_controller
    site_controllers[doctype] = _get_controller()
  File "apps/frappe/frappe/model/base_document.py", line 67, in _get_controller
    class_overrides = frappe.get_hooks("override_doctype_class")
  File "apps/frappe/frappe/__init__.py", line 1511, in get_hooks
    hooks = _dict(_load_app_hooks())
  File "apps/frappe/frappe/utils/caching.py", line 57, in wrapper
    return_val = func(*args, **kwargs)
  File "apps/frappe/frappe/__init__.py", line 1480, in _load_app_hooks
    app_hooks = get_module(f"{app}.hooks")
  File "apps/frappe/frappe/__init__.py", line 1342, in get_module
    return importlib.import_module(modulename)
  File "/usr/lib/python3.10/importlib/__init__.py", line 126, in import_module
    return _bootstrap._gcd_import(name[level:], package, level)
  File "<frozen importlib._bootstrap>", line 1050, in _gcd_import
  File "<frozen importlib._bootstrap>", line 1027, in _find_and_load
  File "<frozen importlib._bootstrap>", line 1006, in _find_and_load_unlocked
  File "<frozen importlib._bootstrap>", line 688, in _load_unlocked
  File "<frozen importlib._bootstrap_external>", line 879, in exec_module
  File "<frozen importlib._bootstrap_external>", line 1017, in get_code
  File "<frozen importlib._bootstrap_external>", line 947, in source_to_code
  File "<frozen importlib._bootstrap>", line 241, in _call_with_frames_removed
  File "apps/stripe_payment/stripe_payment/hooks.py", line 121
    doc_events = {
IndentationError: unexpected indent

2023-09-15 17:20:10,910 ERROR scheduler Exception in Enqueue Events for Site taskerpage.com
Traceback (most recent call last):
  File "apps/frappe/frappe/utils/caching.py", line 55, in wrapper
    return frappe.local.request_cache[func][args_key]
KeyError: 5740354900026072187

During handling of the above exception, another exception occurred:

Traceback (most recent call last):
  File "apps/frappe/frappe/utils/scheduler.py", line 75, in enqueue_events_for_site
    if is_scheduler_inactive():
  File "apps/frappe/frappe/utils/scheduler.py", line 114, in is_scheduler_inactive
    if is_scheduler_disabled(verbose=verbose):
  File "apps/frappe/frappe/utils/scheduler.py", line 127, in is_scheduler_disabled
    frappe.db.get_single_value("System Settings", "enable_scheduler")
  File "apps/frappe/frappe/database/database.py", line 789, in get_single_value
    df = frappe.get_meta(doctype).get_field(fieldname)
  File "apps/frappe/frappe/__init__.py", line 1226, in get_meta
    return frappe.model.meta.get_meta(doctype, cached=cached)
  File "apps/frappe/frappe/model/meta.py", line 65, in get_meta
    meta = Meta(doctype)
  File "apps/frappe/frappe/model/meta.py", line 117, in __init__
    super().__init__("DocType", doctype)
  File "apps/frappe/frappe/model/document.py", line 106, in __init__
    self.load_from_db()
  File "apps/frappe/frappe/model/meta.py", line 123, in load_from_db
    super().load_from_db()
  File "apps/frappe/frappe/model/document.py", line 176, in load_from_db
    self.set(df.fieldname, children)
  File "apps/frappe/frappe/model/base_document.py", line 219, in set
    self.extend(key, value)
  File "apps/frappe/frappe/model/base_document.py", line 260, in extend
    self.append(key, v)
  File "apps/frappe/frappe/model/base_document.py", line 245, in append
    value = self._init_child(value, key)
  File "apps/frappe/frappe/model/base_document.py", line 274, in _init_child
    value = get_controller(doctype)(value)
  File "apps/frappe/frappe/model/base_document.py", line 93, in get_controller
    site_controllers[doctype] = _get_controller()
  File "apps/frappe/frappe/model/base_document.py", line 67, in _get_controller
    class_overrides = frappe.get_hooks("override_doctype_class")
  File "apps/frappe/frappe/__init__.py", line 1511, in get_hooks
    hooks = _dict(_load_app_hooks())
  File "apps/frappe/frappe/utils/caching.py", line 57, in wrapper
    return_val = func(*args, **kwargs)
  File "apps/frappe/frappe/__init__.py", line 1480, in _load_app_hooks
    app_hooks = get_module(f"{app}.hooks")
  File "apps/frappe/frappe/__init__.py", line 1342, in get_module
    return importlib.import_module(modulename)
  File "/usr/lib/python3.10/importlib/__init__.py", line 126, in import_module
    return _bootstrap._gcd_import(name[level:], package, level)
  File "<frozen importlib._bootstrap>", line 1050, in _gcd_import
  File "<frozen importlib._bootstrap>", line 1027, in _find_and_load
  File "<frozen importlib._bootstrap>", line 1006, in _find_and_load_unlocked
  File "<frozen importlib._bootstrap>", line 688, in _load_unlocked
  File "<frozen importlib._bootstrap_external>", line 879, in exec_module
  File "<frozen importlib._bootstrap_external>", line 1017, in get_code
  File "<frozen importlib._bootstrap_external>", line 947, in source_to_code
  File "<frozen importlib._bootstrap>", line 241, in _call_with_frames_removed
  File "apps/stripe_payment/stripe_payment/hooks.py", line 121
    doc_events = {
IndentationError: unexpected indent

2023-09-16 09:48:56,278 ERROR scheduler Exception in Enqueue Events for Site taskerpage.com
Traceback (most recent call last):
  File "env/lib/python3.10/site-packages/pymysql/connections.py", line 616, in connect
    sock = socket.create_connection(
  File "/usr/lib/python3.10/socket.py", line 845, in create_connection
    raise err
  File "/usr/lib/python3.10/socket.py", line 833, in create_connection
    sock.connect(sa)
ConnectionRefusedError: [Errno 111] Connection refused

During handling of the above exception, another exception occurred:

Traceback (most recent call last):
  File "apps/frappe/frappe/utils/scheduler.py", line 75, in enqueue_events_for_site
    if is_scheduler_inactive():
  File "apps/frappe/frappe/utils/scheduler.py", line 114, in is_scheduler_inactive
    if is_scheduler_disabled(verbose=verbose):
  File "apps/frappe/frappe/utils/scheduler.py", line 127, in is_scheduler_disabled
    frappe.db.get_single_value("System Settings", "enable_scheduler")
  File "apps/frappe/frappe/database/database.py", line 786, in get_single_value
    ).run()
  File "apps/frappe/frappe/query_builder/utils.py", line 87, in execute_query
    result = frappe.db.sql(query, params, *args, **kwargs)  # nosemgrep
  File "apps/frappe/frappe/database/database.py", line 201, in sql
    self.connect()
  File "apps/frappe/frappe/database/database.py", line 115, in connect
    self._conn = self.get_connection()
  File "apps/frappe/frappe/database/mariadb/database.py", line 98, in get_connection
    conn = self._get_connection()
  File "apps/frappe/frappe/database/mariadb/database.py", line 104, in _get_connection
    return self.create_connection()
  File "apps/frappe/frappe/database/mariadb/database.py", line 107, in create_connection
    return pymysql.connect(**self.get_connection_settings())
  File "env/lib/python3.10/site-packages/pymysql/connections.py", line 352, in __init__
    self.connect()
  File "env/lib/python3.10/site-packages/pymysql/connections.py", line 668, in connect
    raise exc
pymysql.err.OperationalError: (2003, "Can't connect to MySQL server on '127.0.0.1' ([Errno 111] Connection refused)")

2023-09-16 09:49:57,037 ERROR scheduler Exception in Enqueue Events for Site taskerpage.com
Traceback (most recent call last):
  File "env/lib/python3.10/site-packages/pymysql/connections.py", line 616, in connect
    sock = socket.create_connection(
  File "/usr/lib/python3.10/socket.py", line 845, in create_connection
    raise err
  File "/usr/lib/python3.10/socket.py", line 833, in create_connection
    sock.connect(sa)
ConnectionRefusedError: [Errno 111] Connection refused

During handling of the above exception, another exception occurred:

Traceback (most recent call last):
  File "apps/frappe/frappe/utils/scheduler.py", line 75, in enqueue_events_for_site
    if is_scheduler_inactive():
  File "apps/frappe/frappe/utils/scheduler.py", line 114, in is_scheduler_inactive
    if is_scheduler_disabled(verbose=verbose):
  File "apps/frappe/frappe/utils/scheduler.py", line 127, in is_scheduler_disabled
    frappe.db.get_single_value("System Settings", "enable_scheduler")
  File "apps/frappe/frappe/database/database.py", line 786, in get_single_value
    ).run()
  File "apps/frappe/frappe/query_builder/utils.py", line 87, in execute_query
    result = frappe.db.sql(query, params, *args, **kwargs)  # nosemgrep
  File "apps/frappe/frappe/database/database.py", line 201, in sql
    self.connect()
  File "apps/frappe/frappe/database/database.py", line 115, in connect
    self._conn = self.get_connection()
  File "apps/frappe/frappe/database/mariadb/database.py", line 98, in get_connection
    conn = self._get_connection()
  File "apps/frappe/frappe/database/mariadb/database.py", line 104, in _get_connection
    return self.create_connection()
  File "apps/frappe/frappe/database/mariadb/database.py", line 107, in create_connection
    return pymysql.connect(**self.get_connection_settings())
  File "env/lib/python3.10/site-packages/pymysql/connections.py", line 352, in __init__
    self.connect()
  File "env/lib/python3.10/site-packages/pymysql/connections.py", line 668, in connect
    raise exc
pymysql.err.OperationalError: (2003, "Can't connect to MySQL server on '127.0.0.1' ([Errno 111] Connection refused)")

2023-09-16 09:51:03,069 ERROR scheduler Exception in Enqueue Events for Site taskerpage.com
Traceback (most recent call last):
  File "env/lib/python3.10/site-packages/pymysql/connections.py", line 616, in connect
    sock = socket.create_connection(
  File "/usr/lib/python3.10/socket.py", line 845, in create_connection
    raise err
  File "/usr/lib/python3.10/socket.py", line 833, in create_connection
    sock.connect(sa)
ConnectionRefusedError: [Errno 111] Connection refused

During handling of the above exception, another exception occurred:

Traceback (most recent call last):
  File "apps/frappe/frappe/utils/scheduler.py", line 75, in enqueue_events_for_site
    if is_scheduler_inactive():
  File "apps/frappe/frappe/utils/scheduler.py", line 114, in is_scheduler_inactive
    if is_scheduler_disabled(verbose=verbose):
  File "apps/frappe/frappe/utils/scheduler.py", line 127, in is_scheduler_disabled
    frappe.db.get_single_value("System Settings", "enable_scheduler")
  File "apps/frappe/frappe/database/database.py", line 786, in get_single_value
    ).run()
  File "apps/frappe/frappe/query_builder/utils.py", line 87, in execute_query
    result = frappe.db.sql(query, params, *args, **kwargs)  # nosemgrep
  File "apps/frappe/frappe/database/database.py", line 201, in sql
    self.connect()
  File "apps/frappe/frappe/database/database.py", line 115, in connect
    self._conn = self.get_connection()
  File "apps/frappe/frappe/database/mariadb/database.py", line 98, in get_connection
    conn = self._get_connection()
  File "apps/frappe/frappe/database/mariadb/database.py", line 104, in _get_connection
    return self.create_connection()
  File "apps/frappe/frappe/database/mariadb/database.py", line 107, in create_connection
    return pymysql.connect(**self.get_connection_settings())
  File "env/lib/python3.10/site-packages/pymysql/connections.py", line 352, in __init__
    self.connect()
  File "env/lib/python3.10/site-packages/pymysql/connections.py", line 668, in connect
    raise exc
pymysql.err.OperationalError: (2003, "Can't connect to MySQL server on '127.0.0.1' ([Errno 111] Connection refused)")

2023-09-17 19:58:51,299 ERROR scheduler Exception in Enqueue Events for Site taskerpage.com
Traceback (most recent call last):
  File "env/lib/python3.10/site-packages/redis/connection.py", line 1198, in get_connection
    if connection.can_read():
  File "env/lib/python3.10/site-packages/redis/connection.py", line 734, in can_read
    return self._parser.can_read(timeout)
  File "env/lib/python3.10/site-packages/redis/connection.py", line 416, in can_read
    return self.read_from_socket(timeout=timeout,
  File "env/lib/python3.10/site-packages/redis/connection.py", line 429, in read_from_socket
    raise ConnectionError(SERVER_CLOSED_CONNECTION_ERROR)
redis.exceptions.ConnectionError: Connection closed by server.

During handling of the above exception, another exception occurred:

Traceback (most recent call last):
  File "env/lib/python3.10/site-packages/redis/connection.py", line 559, in connect
    sock = self._connect()
  File "env/lib/python3.10/site-packages/redis/connection.py", line 615, in _connect
    raise err
  File "env/lib/python3.10/site-packages/redis/connection.py", line 603, in _connect
    sock.connect(socket_address)
ConnectionRefusedError: [Errno 111] Connection refused

During handling of the above exception, another exception occurred:

Traceback (most recent call last):
  File "apps/frappe/frappe/utils/scheduler.py", line 78, in enqueue_events_for_site
    enqueue_events(site=site)
  File "apps/frappe/frappe/utils/scheduler.py", line 96, in enqueue_events
    queued_jobs = get_jobs(site=site, key="job_type").get(site) or []
  File "apps/frappe/frappe/utils/background_jobs.py", line 303, in get_jobs
    jobs = q.jobs + get_running_jobs_in_queue(q)
  File "env/lib/python3.10/site-packages/rq/queue.py", line 218, in jobs
    return self.get_jobs()
  File "env/lib/python3.10/site-packages/rq/queue.py", line 207, in get_jobs
    job_ids = self.get_job_ids(offset, length)
  File "env/lib/python3.10/site-packages/rq/queue.py", line 203, in get_job_ids
    self.connection.lrange(self.key, start, end)]
  File "env/lib/python3.10/site-packages/redis/client.py", line 1975, in lrange
    return self.execute_command('LRANGE', name, start, end)
  File "env/lib/python3.10/site-packages/redis/client.py", line 898, in execute_command
    conn = self.connection or pool.get_connection(command_name, **options)
  File "env/lib/python3.10/site-packages/redis/connection.py", line 1202, in get_connection
    connection.connect()
  File "env/lib/python3.10/site-packages/redis/connection.py", line 563, in connect
    raise ConnectionError(self._error_message(e))
redis.exceptions.ConnectionError: Error 111 connecting to localhost:11000. Connection refused.

